Workbook

Sheet Nominated Participants
A1: Nomination Form Academic Mobility Exchange for Undergraduate and Master at Airlangga (AMERTA)
A2: * Please note that application process is still needed after the nomination. Please refer to https://global.unair.ac.id/amerta/ for undergraduate and https://global.unair.ac.id/amerta-for-master-program/ master program.
A7: Nominated Students
A9: No | B9: First Name(Given) | C9: Last Name(Family) | D9: Gender(Sex) | E9: Study Level (Undergraduate/Master) | F9: Major at Home (College/Major) | G9: Home University | H9: Nationality
A10: 1 | B10: Anissa | C10: Saidani | D10: Female | E10: Undergraduate | F10: Economy and Management in bilingual English | G10: Université Le Havre Normandie | H10: French
A11: 2 | B11: Nesrine | C11: AGGOUN | D11: Female | E11: Undergraduate | F11: Economy | G11: Université Le Havre Normandie | H11: French
A12: 3 | B12: Carol | C12: Landeros Silva | D12: Female | F12: Management and International Business | G12: Universidad Panamericana | H12: Mexican
A13: 4 | B13: James | C13: Martin | D13: Male | E13: Undergraduate | F13: Commerce | G13: Deakin University | H13: Australian
A14: 5 | B14: TITHTHEARA | C14: TA | D14: Male | E14: Undergraduate | F14: Law | G14: Royal University of Law and Economics | H14: Cambodian
A15: 6 | B15: VICHEKA | C15: CHAN | D15: Female | E15: Undergraduate | F15: Law | G15: Royal University of Law and Economics | H15: Cambodian
A16: 7 | B16: Nur Nabilah | C16: binti Mohd. Shahfiee | D16: Female | F16: English Studies | G16: Universiti Brunei Darussalam | H16: Bruneian
A17: 8 | B17: Mu'izzul Iza'an | C17: Edie Jupry | D17: Male | F17: Data Science | G17: Universiti Brunei Darussalam | H17: Bruneian
A18: 9 | B18: Chin Kirby | C18: Apellido | D18: Female | E18: Undergraduate | F18: Social Studies | G18: Pangasinan State University | H18: Filipino
A19: 10 | B19: Ace Christian Rey | C19: Miguel | D19: Male | E19: Undergraduate | F19: Economics | G19: Pangasinan State University | H19: Filipino
A20: 11 | B20: Eirnest Dave Son | C20: Eliver | D20: Male | E20: Master | F20: Fisheries | G20: Pangasinan State University | H20: Filipino
A21: 12 | B21: Daniel | C21: Facun | D21: Male | E21: Master | F21: Fisheries | G21: Pangasinan State University | H21: Filipino
A22: 13 | B22: Ian | C22: Navarro | D22: Male | E22: Undergraduate | F22: Economics | G22: Pangasinan State University | H22: Filipino
A23: 14 | B23: Pas Juliven | C23: Miana | D23: Male | E23: Undergraduate | F23: Public Administration | G23: Pangasinan State University | H23: Filipino
A24: 15 | B24: Rica Grace | C24: Esmeña | D24: Female | E24: Undergraduate | F24: Social Studies | G24: Pangasinan State University | H24: Filipino
A25: 16 | B25: Galileo | C25: Tamayo | D25: Male | E25: Undergraduate | F25: Social Studies | G25: Pangasinan State University | H25: Filipino
A26: 17 | B26: Giela Mae | C26: Manangan | D26: Female | E26: Undergraduate | F26: Social Studies | G26: Pangasinan State University | H26: Filipino
A27: 18 | B27: James Patrick | C27: Nafarrete | D27: Male | E27: Undergraduate | F27: Social Studies | G27: Pangasinan State University | H27: Filipino
A28: 19 | B28: Jaer Krishan | C28: Bautista | D28: Female | E28: Undergraduate | F28: Nursing | G28: Pangasinan State University | H28: Filipino
A29: 20 | B29: Cassandra Carme | C29: Sapera | D29: Female | E29: Undergraduate | F29: Nursing | G29: Pangasinan State University | H29: Filipino
... A45: 36 | B45: Arianne | C45: Bal-ot | D45: Female | E45: Undergraduate | F45: Nursing | G45: Pangasinan State University | H45: Filipino
A46: 37 | B46: Maciej | C46: Dobrowolski | D46: Male | E46: Undergraduate | G46: University of Warsaw | H46: Polish
A47: 38 | B47: Jakub | C47: Flisek | D47: Male | E47: Undergraduate | G47: University of Warsaw | H47: Polish
A48: 39 | B48: Maksymilian | C48: Budzyński | D48: Male | E48: Undergraduate | G48: University of Warsaw | H48: Polish
A49: 40 | B49: Zainab | C49: Imran | D49: Female | E49: Undergraduate | G49: Lahore University of Management Sciences (LUMS) | H49: Pakistani
A50: 41 | B50: Iskander | C50: Aminov | D50: Male | E50: Undergraduate | F50: Biotechnology | G50: Satbayev Univeristy | H50: Kazakhstan
A51: 42 | B51: Lukas | C51: Neuwirht | D51: Male | E51: Undergraduate | G51: Maastricht University | H51: German
A52: 43 | B52: Jonathan | C52: Soekah | G52: Maastricht University | H52: German

Sheet Welfare
A1: Nomination Form Academic Mobility Exchange for Undergraduate and Master at Airlangga (AMERTA)
A2: * Please note that application process is still needed after the nomination. Please refer to https://global.unair.ac.id/amerta/ for undergraduate and https://global.unair.ac.id/amerta-for-master-program/ master program.
A7: Nominated Students
A9: No | B9: Status | C9: Letter of Acceptance | D9: First Name(Given) | E9: Last Name(Family) | F9: Gender(Sex) | G9: Home University | H9: Nationality | I9: Student's email | J9: Emailed Accommodation | K9: Accommodation | L9: Arrival Date | M9: Arrival Time | N9: Bank Account | O9: BEST Buddies | P9: AMERTA Student's Contact
A10: ='Nominated Participants'!A10 -> 1 | B10: ='Nominated Participants'!#REF! -> #REF! | C10: ='Nominated Participants'!#REF! -> #REF! | D10: ='Nominated Participants'!B10 -> Anissa | E10: ='Nominated Participants'!C10 -> Saidani | F10: ='Nominated Participants'!D10 -> Female | G10: ='Nominated Participants'!G10 -> Université Le Havre Normandie | H10: ='Nominated Participants'!H10 -> French | I10: ='Nominated Participants'!G10 -> Université Le Havre Normandie | J10: Done | K10: Taman Melati 1236 | L10: 45687 | M10: 0.99305556 | N10: 142-00-2410341-7 | O10: Keisya | P10: wa.me/33649552334
A11: ='Nominated Participants'!A11 -> 2 | B11: ='Nominated Participants'!#REF! -> #REF! | C11: ='Nominated Participants'!#REF! -> #REF! | D11: ='Nominated Participants'!B11 -> Nesrine | E11: ='Nominated Participants'!C11 -> AGGOUN | F11: ='Nominated Participants'!D11 -> Female | G11: ='Nominated Participants'!G11 -> Université Le Havre Normandie | H11: ='Nominated Participants'!H11 -> French | I11: ='Nominated Participants'!G11 -> Université Le Havre Normandie | J11: Done | K11: Asrama Putri | L11: ARRIVED | M11: ARRIVED | N11: 1420023293698 | O11: Tata
A12: ='Nominated Participants'!A12 -> 3 | B12: ='Nominated Participants'!#REF! -> #REF! | C12: ='Nominated Participants'!#REF! -> #REF! | D12: ='Nominated Participants'!B12 -> Carol | E12: ='Nominated Participants'!C12 -> Landeros Silva | F12: ='Nominated Participants'!D12 -> Female | G12: ='Nominated Participants'!G12 -> Universidad Panamericana | H12: ='Nominated Participants'!H12 -> Mexican | I12: ='Nominated Participants'!G12 -> Universidad Panamericana | J12: Done | K12: Gunawangsa Manyar Tower A, 1006 | L12: 45691 | M12: 0.75694444 | N12: 1420024106873 | O12: Naya | P12: wa.me/5213314387794
A13: ='Nominated Participants'!A13 -> 4 | B13: ='Nominated Participants'!#REF! -> #REF! | C13: ='Nominated Participants'!#REF! -> #REF! | D13: ='Nominated Participants'!B13 -> James | E13: ='Nominated Participants'!C13 -> Martin | F13: ='Nominated Participants'!D13 -> Male | G13: ='Nominated Participants'!G13 -> Deakin University | H13: ='Nominated Participants'!H13 -> Australian | I13: ='Nominated Participants'!G13 -> Deakin University | J13: Done | K13: Gunawangsa Manyar Tower B, 2332 | L13: 45695 | M13: 0.38888889 | N13: 1420024128018 | O13: Faisol | P13: wa.me/61483207074
A14: ='Nominated Participants'!A14 -> 5 | B14: ='Nominated Participants'!#REF! -> #REF! | C14: ='Nominated Participants'!#REF! -> #REF! | D14: ='Nominated Participants'!B14 -> TITHTHEARA | E14: ='Nominated Participants'!C14 -> TA | F14: ='Nominated Participants'!D14 -> Male | G14: ='Nominated Participants'!G14 -> Royal University of Law and Economics | H14: ='Nominated Participants'!H14 -> Cambodian | I14: ='Nominated Participants'!G14 -> Royal University of Law and Economics | J14: Done | K14: Gunawangsa Manyar Tower A, 2018a | L14: 45690 | M14: 0.38194444 | O14: Eudith | P14: wa.me/85512601474
A15: ='Nominated Participants'!A15 -> 6 | B15: ='Nominated Participants'!#REF! -> #REF! | C15: ='Nominated Participants'!#REF! -> #REF! | D15: ='Nominated Participants'!B15 -> VICHEKA | E15: ='Nominated Participants'!C15 -> CHAN | F15: ='Nominated Participants'!D15 -> Female | G15: ='Nominated Participants'!G15 -> Royal University of Law and Economics | H15: ='Nominated Participants'!H15 -> Cambodian | I15: ='Nominated Participants'!G15 -> Royal University of Law and Economics | J15: Done | K15: Gunawangsa Manyar Tower A, 1006 | L15: 45690 | M15: 0.38194444 | N15: 1420024108580 | O15: Naya | P15: wa.me/85511438890
A16: ='Nominated Participants'!A16 -> 7 | B16: ='Nominated Participants'!#REF! -> #REF! | C16: ='Nominated Participants'!#REF! -> #REF! | D16: ='Nominated Participants'!B16 -> Nur Nabilah | E16: ='Nominated Participants'!C16 -> binti Mohd. Shahfiee | F16: ='Nominated Participants'!D16 -> Female | G16: ='Nominated Participants'!G16 -> Universiti Brunei Darussalam | H16: ='Nominated Participants'!H16 -> Bruneian | I16: ='Nominated Participants'!G16 -> Universiti Brunei Darussalam | J16: Done | K16: belum confirm | N16: 142-00-2410790-5 | O16: Yasmine | P16: wa.me/6738219912
A17: ='Nominated Participants'!A17 -> 8 | B17: ='Nominated Participants'!#REF! -> #REF! | C17: ='Nominated Participants'!#REF! -> #REF! | D17: ='Nominated Participants'!B17 -> Mu'izzul Iza'an | E17: ='Nominated Participants'!C17 -> Edie Jupry | F17: ='Nominated Participants'!D17 -> Male | G17: ='Nominated Participants'!G17 -> Universiti Brunei Darussalam | H17: ='Nominated Participants'!H17 -> Bruneian | I17: ='Nominated Participants'!G17 -> Universiti Brunei Darussalam | J17: Done | K17: belum confirm | O17: Yasmine | P17: wa.me/6737236560
A18: ='Nominated Participants'!A18 -> 9 | B18: ='Nominated Participants'!#REF! -> #REF! | C18: ='Nominated Participants'!#REF! -> #REF! | D18: ='Nominated Participants'!B19 -> Ace Christian Rey | E18: ='Nominated Participants'!C19 -> Miguel | F18: ='Nominated Participants'!D19 -> Male | G18: ='Nominated Participants'!G19 -> Pangasinan State University | H18: ='Nominated Participants'!H19 -> Filipino | I18: ='Nominated Participants'!G19 -> Pangasinan State University | J18: Cancelled | O18: Allan
A19: ='Nominated Participants'!A19 -> 10 | B19: ='Nominated Participants'!#REF! -> #REF! | C19: ='Nominated Participants'!#REF! -> #REF! | D19: ='Nominated Participants'!B20 -> Eirnest Dave Son | E19: ='Nominated Participants'!C20 -> Eliver | F19: ='Nominated Participants'!D20 -> Male | G19: ='Nominated Participants'!G20 -> Pangasinan State University | H19: ='Nominated Participants'!H20 -> Filipino | I19: ='Nominated Participants'!G20 -> Pangasinan State University | J19: Cancelled | O19: Eudith
A20: ='Nominated Participants'!A20 -> 11 | B20: ='Nominated Participants'!#REF! -> #REF! | C20: ='Nominated Participants'!#REF! -> #REF! | D20: ='Nominated Participants'!B21 -> Daniel | E20: ='Nominated Participants'!C21 -> Facun | F20: ='Nominated Participants'!D21 -> Male | G20: ='Nominated Participants'!G21 -> Pangasinan State University | H20: ='Nominated Participants'!H21 -> Filipino | I20: ='Nominated Participants'!G21 -> Pangasinan State University | J20: Cancelled | O20: Faisol
A21: ='Nominated Participants'!A21 -> 12 | B21: ='Nominated Participants'!#REF! -> #REF! | C21: ='Nominated Participants'!#REF! -> #REF! | D21: ='Nominated Participants'!B22 -> Ian | E21: ='Nominated Participants'!C22 -> Navarro | F21: ='Nominated Participants'!D22 -> Male | G21: ='Nominated Participants'!G22 -> Pangasinan State University | H21: ='Nominated Participants'!H22 -> Filipino | I21: ='Nominated Participants'!G22 -> Pangasinan State University | J21: Haven't
A22: ='Nominated Participants'!A22 -> 13 | B22: ='Nominated Participants'!#REF! -> #REF! | C22: ='Nominated Participants'!#REF! -> #REF! | D22: ='Nominated Participants'!B24 -> Rica Grace | E22: ='Nominated Participants'!C24 -> Esmeña | F22: ='Nominated Participants'!D24 -> Female | G22: ='Nominated Participants'!G24 -> Pangasinan State University | H22: ='Nominated Participants'!H24 -> Filipino | I22: ='Nominated Participants'!G24 -> Pangasinan State University | J22: Cancelled | O22: Agatha
A23: ='Nominated Participants'!A23 -> 14 | B23: ='Nominated Participants'!#REF! -> #REF! | C23: ='Nominated Participants'!#REF! -> #REF! | D23: ='Nominated Participants'!B25 -> Galileo | E23: ='Nominated Participants'!C25 -> Tamayo | F23: ='Nominated Participants'!D25 -> Male | G23: ='Nominated Participants'!G25 -> Pangasinan State University | H23: ='Nominated Participants'!H25 -> Filipino | I23: ='Nominated Participants'!G25 -> Pangasinan State University | J23: Done | K23: Gunawangsa Manyar, Tower A, 625 | O23: Allan
A24: ='Nominated Participants'!A24 -> 15 | B24: Applied | C24: Sent | D24: Marck Esthevyn V. | E24: Cabiso | F24: Male | G24: Pangasinan State University | H24: Filipino | J24: Done | K24: Gunawangsa Manyar, Tower A, 625 | N24: 142-00-2411664-1
A25: ='Nominated Participants'!A25 -> 16 | B25: ='Nominated Participants'!#REF! -> #REF! | C25: ='Nominated Participants'!#REF! -> #REF! | D25: ='Nominated Participants'!B26 -> Giela Mae | E25: ='Nominated Participants'!C26 -> Manangan | F25: ='Nominated Participants'!D26 -> Female | G25: ='Nominated Participants'!G26 -> Pangasinan State University | H25: ='Nominated Participants'!H26 -> Filipino | I25: ='Nominated Participants'!G26 -> Pangasinan State University | J25: Cancelled | O25: Aca
A26: ='Nominated Participants'!A26 -> 17 | B26: ='Nominated Participants'!#REF! -> #REF! | C26: ='Nominated Participants'!#REF! -> #REF! | D26: ='Nominated Participants'!B46 -> Maciej | E26: ='Nominated Participants'!C46 -> Dobrowolski | F26: ='Nominated Participants'!D46 -> Male | G26: ='Nominated Participants'!G46 -> University of Warsaw | H26: ='Nominated Participants'!H46 -> Polish | I26: ='Nominated Participants'!G46 -> University of Warsaw | J26: Processed | O26: Kala | P26: wa.me/48533993222
A27: ='Nominated Participants'!A27 -> 18 | B27: ='Nominated Participants'!#REF! -> #REF! | C27: ='Nominated Participants'!#REF! -> #REF! | D27: ='Nominated Participants'!B47 -> Jakub | E27: ='Nominated Participants'!C47 -> Flisek | F27: ='Nominated Participants'!D47 -> Male | G27: ='Nominated Participants'!G47 -> University of Warsaw | H27: ='Nominated Participants'!H47 -> Polish | I27: ='Nominated Participants'!G47 -> University of Warsaw | J27: Done | K27: Educity Apartment, Tower Y, 2807 | L27: 45696 | M27: 0.38888889 | O27: Tafrina | P27: wa.me/48789319889
A28: ='Nominated Participants'!A28 -> 19 | B28: ='Nominated Participants'!#REF! -> #REF! | C28: ='Nominated Participants'!#REF! -> #REF! | D28: ='Nominated Participants'!B48 -> Maksymilian | E28: ='Nominated Participants'!C48 -> Budzyński | F28: ='Nominated Participants'!D48 -> Male | G28: ='Nominated Participants'!G48 -> University of Warsaw | H28: ='Nominated Participants'!H48 -> Polish | I28: ='Nominated Participants'!G48 -> University of Warsaw | J28: Done | K28: Educity Apartment, Tower Y, 2807 | L28: 45696 | M28: 0.38888889 | O28: Cher | P28: wa.me/48608320110
A29: ='Nominated Participants'!A29 -> 20 | B29: ='Nominated Participants'!#REF! -> #REF! | C29: ='Nominated Participants'!#REF! -> #REF! | D29: ='Nominated Participants'!B49 -> Zainab | E29: ='Nominated Participants'!C49 -> Imran | F29: ='Nominated Participants'!D49 -> Female | G29: ='Nominated Participants'!G49 -> Lahore University of Management Sciences (LUMS) | H29: ='Nominated Participants'!H49 -> Pakistani | I29: ='Nominated Participants'!G49 -> Lahore University of Management Sciences (LUMS) | J29: Replied | O29: Rafifah | P29: wa.me/923252956558
A30: ='Nominated Participants'!A30 -> 21 | B30: ='Nominated Participants'!#REF! -> #REF! | C30: ='Nominated Participants'!#REF! -> #REF! | D30: ='Nominated Participants'!B50 -> Iskander | E30: ='Nominated Participants'!C50 -> Aminov | F30: ='Nominated Participants'!D50 -> Male | G30: ='Nominated Participants'!G50 -> Satbayev Univeristy | H30: ='Nominated Participants'!H50 -> Kazakhstan | I30: ='Nominated Participants'!G50 -> Satbayev Univeristy | J30: Haven't | O30: Allan
A31: ='Nominated Participants'!A31 -> 22 | B31: ='Nominated Participants'!#REF! -> #REF! | C31: ='Nominated Participants'!#REF! -> #REF! | D31: ='Nominated Participants'!B51 -> Lukas | E31: ='Nominated Participants'!C51 -> Neuwirht | F31: ='Nominated Participants'!D51 -> Male | G31: ='Nominated Participants'!G51 -> Maastricht University | H31: Germany | I31: ='Nominated Participants'!G51 -> Maastricht University | J31: Done | K31: Educity Apartment, Tower P, 3026 | L31: 45685 | M31: 0.79861111 | O31: Eudith | P31: wa.me/4916093239177
B32: ='Nominated Participants'!#REF! -> #REF! | C32: ='Nominated Participants'!#REF! -> #REF! | D32: ='Nominated Participants'!B52 -> Jonathan | E32: ='Nominated Participants'!C52 -> Soekah | F32: ='Nominated Participants'!D52 -> 0 | G32: ='Nominated Participants'!G52 -> Maastricht University | H32: ='Nominated Participants'!F52 -> 0 | I32: ='Nominated Participants'!G52 -> Maastricht University
B33: ='Nominated Participants'!#REF! -> #REF! | C33: ='Nominated Participants'!#REF! -> #REF! | D33: ='Nominated Participants'!B53 -> 0 | E33: ='Nominated Participants'!C53 -> 0 | F33: ='Nominated Participants'!D53 -> 0 | G33: ='Nominated Participants'!G53 -> 0 | H33: ='Nominated Participants'!F53 -> 0 | I33: ='Nominated Participants'!G53 -> 0
B34: ='Nominated Participants'!#REF! -> #REF! | C34: ='Nominated Participants'!#REF! -> #REF! | D34: ='Nominated Participants'!B54 -> 0 | E34: ='Nominated Participants'!C54 -> 0 | F34: ='Nominated Participants'!D54 -> 0 | G34: ='Nominated Participants'!G54 -> 0 | H34: ='Nominated Participants'!F54 -> 0 | I34: ='Nominated Participants'!G54 -> 0
B35: ='Nominated Participants'!#REF! -> #REF! | C35: ='Nominated Participants'!#REF! -> #REF! | D35: ='Nominated Participants'!B55 -> 0 | E35: ='Nominated Participants'!C55 -> 0 | F35: ='Nominated Participants'!D55 -> 0 | G35: ='Nominated Participants'!G55 -> 0 | H35: ='Nominated Participants'!F55 -> 0 | I35: ='Nominated Participants'!G55 -> 0
B36: ='Nominated Participants'!#REF! -> #REF! | C36: ='Nominated Participants'!#REF! -> #REF! | D36: ='Nominated Participants'!B56 -> 0 | E36: ='Nominated Participants'!C56 -> 0 | F36: ='Nominated Participants'!D56 -> 0 | G36: ='Nominated Participants'!G56 -> 0 | H36: ='Nominated Participants'!F56 -> 0 | I36: ='Nominated Participants'!G56 -> 0
B37: ='Nominated Participants'!#REF! -> #REF! | C37: ='Nominated Participants'!#REF! -> #REF! | D37: ='Nominated Participants'!B57 -> 0 | E37: ='Nominated Participants'!C57 -> 0 | F37: ='Nominated Participants'!D57 -> 0 | G37: ='Nominated Participants'!G57 -> 0 | H37: ='Nominated Participants'!F57 -> 0 | I37: ='Nominated Participants'!G57 -> 0
B38: ='Nominated Participants'!#REF! -> #REF! | C38: ='Nominated Participants'!#REF! -> #REF! | D38: ='Nominated Participants'!B58 -> 0 | E38: ='Nominated Participants'!C58 -> 0 | F38: ='Nominated Participants'!D58 -> 0 | G38: ='Nominated Participants'!G58 -> 0 | H38: ='Nominated Participants'!F58 -> 0 | I38: ='Nominated Participants'!G58 -> 0
B39: ='Nominated Participants'!#REF! -> #REF! | C39: ='Nominated Participants'!#REF! -> #REF! | D39: ='Nominated Participants'!B59 -> 0 | E39: ='Nominated Participants'!C59 -> 0 | F39: ='Nominated Participants'!D59 -> 0 | G39: ='Nominated Participants'!G59 -> 0 | H39: ='Nominated Participants'!F59 -> 0 | I39: ='Nominated Participants'!G59 -> 0
B40: ='Nominated Participants'!#REF! -> #REF! | C40: ='Nominated Participants'!#REF! -> #REF! | D40: ='Nominated Participants'!B60 -> 0 | E40: ='Nominated Participants'!C60 -> 0 | F40: ='Nominated Participants'!D60 -> 0 | G40: ='Nominated Participants'!G60 -> 0 | H40: ='Nominated Participants'!F60 -> 0 | I40: ='Nominated Participants'!G60 -> 0
B41: ='Nominated Participants'!#REF! -> #REF! | C41: ='Nominated Participants'!#REF! -> #REF! | D41: ='Nominated Participants'!B61 -> 0 | E41: ='Nominated Participants'!C61 -> 0 | F41: ='Nominated Participants'!D61 -> 0 | G41: ='Nominated Participants'!G61 -> 0 | H41: ='Nominated Participants'!F61 -> 0 | I41: ='Nominated Participants'!G61 -> 0
B42: ='Nominated Participants'!#REF! -> #REF! | C42: ='Nominated Participants'!#REF! -> #REF! | D42: ='Nominated Participants'!B62 -> 0 | E42: ='Nominated Participants'!C62 -> 0 | F42: ='Nominated Participants'!D62 -> 0 | G42: ='Nominated Participants'!G62 -> 0 | H42: ='Nominated Participants'!F62 -> 0 | I42: ='Nominated Participants'!G62 -> 0
B43: ='Nominated Participants'!#REF! -> #REF! | C43: ='Nominated Participants'!#REF! -> #REF! | D43: ='Nominated Participants'!B63 -> 0 | E43: ='Nominated Participants'!C63 -> 0 | F43: ='Nominated Participants'!D63 -> 0 | G43: ='Nominated Participants'!G63 -> 0 | H43: ='Nominated Participants'!F63 -> 0 | I43: ='Nominated Participants'!G63 -> 0
... B48: ='Nominated Participants'!#REF! -> #REF! | C48: ='Nominated Participants'!#REF! -> #REF! | D48: ='Nominated Participants'!B68 -> 0 | E48: ='Nominated Participants'!C68 -> 0 | F48: ='Nominated Participants'!D68 -> 0 | G48: ='Nominated Participants'!G68 -> 0 | H48: ='Nominated Participants'!F68 -> 0 | I48: ='Nominated Participants'!G68 -> 0
B49: ='Nominated Participants'!#REF! -> #REF! | C49: ='Nominated Participants'!#REF! -> #REF! | D49: ='Nominated Participants'!B69 -> 0 | E49: ='Nominated Participants'!C69 -> 0 | F49: ='Nominated Participants'!D69 -> 0 | G49: ='Nominated Participants'!G69 -> 0 | H49: ='Nominated Participants'!F69 -> 0
...
